Workbook
Name cer_pro: All_India_Index_Upto_April23__13[[#All],[Cereals and products]]
Name clothing_foot: All_India_Index_Upto_April23__13[[#All],[Clothing and footwear]]
Name clothings: All_India_Index_Upto_April23__13[[#All],[Clothing]]
Name education: All_India_Index_Upto_April23__13[[#All],[Education]]
Name egg: All_India_Index_Upto_April23__13[[#All],[Egg]]
Name Food_beverages: All_India_Index_Upto_April23__13[[#All],[Food and beverages]]
Name Food_buckets_avg: All_India_Index_Upto_April23__134[[#All],[Food buckts avg]]
Name Footware: All_India_Index_Upto_April23__13[[#All],[Footwear]]
Name fruits: All_India_Index_Upto_April23__13[[#All],[Fruits]]
Name Fuel_lights: All_India_Index_Upto_April23__13[[#All],[Fuel and light]]
Name General_index: All_India_Index_Upto_April23__13[[#All],[General index]]
Name health: All_India_Index_Upto_April23__13[[#All],[Health]]
Name house_goods_servies: All_India_Index_Upto_April23__13[[#All],[Household goods and services]]
Name Housing: All_India_Index_Upto_April23__13[[#All],[Housing]]
Name meat_fish: All_India_Index_Upto_April23__13[[#All],[Meat and fish]]
Name Milk_pro: All_India_Index_Upto_April23__13[[#All],[Milk and products]]
Name miscellaneous: All_India_Index_Upto_April23__13[[#All],[Miscellaneous]]
Name months: All_India_Index_Upto_April23__13[[#All],[Month]]
Name non_alcoholic: All_India_Index_Upto_April23__13[[#All],[Non-alcoholic beverages]]
Name oils_fts: All_India_Index_Upto_April23__13[[#All],[Oils and fats]]
Name pan_tabacco: All_India_Index_Upto_April23__13[[#All],[Pan, tobacco and intoxicants]]
Name persinal_care_effects: All_India_Index_Upto_April23__13[[#All],[Personal care and effects]]
Name pre_meal: All_India_Index_Upto_April23__13[[#All],[Prepared meals, snacks, sweets etc.]]
Name Pulses_prod: All_India_Index_Upto_April23__13[[#All],[Pulses and products]]
Name recreation_amusement: All_India_Index_Upto_April23__13[[#All],[Recreation and amusement]]
Name sector: All_India_Index_Upto_April23__13[[#All],[Sector]]
Name spices: All_India_Index_Upto_April23__13[[#All],[Spices]]
Name sugar_confections: All_India_Index_Upto_April23__13[[#All],[Sugar and Confectionery]]
Name trans_comu: All_India_Index_Upto_April23__13[[#All],[Transport and communication]]
Name vegetables: All_India_Index_Upto_April23__13[[#All],[Vegetables]]
Name year: All_India_Index_Upto_April23__13[[#All],[Year]]

Sheet All_India_Index_Upto_April23 (1
A1: Sector | B1: Year | C1: Month | D1: Cereals and products | E1: Meat and fish | F1: Egg | G1: Milk and products | H1: Oils and fats | I1: Fruits | J1: Vegetables | K1: Pulses and products | L1: Sugar and Confectionery | M1: Spices | N1: Non-alcoholic beverages | O1: Prepared meals, snacks, sweets etc. | P1: Food and beverages | Q1: Pan, tobacco and intoxicants | R1: Clothing | S1: Footwear | T1: Clothing and footwear | U1: Housing | V1: Fuel and light | W1: Household goods and services | X1: Health | Y1: Transport and communication | Z1: Recreation and amusement | AA1: Education | AB1: Personal care and effects | AC1: Miscellaneous | AD1: General index
A2: Rural | B2: 2013 | C2: January | D2: 107.5 | E2: 106.3 | F2: 108.1 | G2: 104.9 | H2: 106.1 | I2: 103.9 | J2: 101.9 | K2: 106.1 | L2: 106.8 | M2: 103.1 | N2: 104.8 | O2: 106.7 | P2: 105.5 | Q2: 105.1 | R2: 106.5 | S2: 105.8 | T2: 106.4 | U2: NA | V2: 105.5 | W2: 104.8 | X2: 104 | Y2: 103.3 | Z2: 103.4 | AA2: 103.8 | AB2: 104.7 | AC2: 104 | AD2: 105.1
A3: Urban | B3: 2013 | C3: January | D3: 110.5 | E3: 109.1 | F3: 113 | G3: 103.6 | H3: 103.4 | I3: 102.3 | J3: 102.9 | K3: 105.8 | L3: 105.1 | M3: 101.8 | N3: 105.1 | O3: 107.9 | P3: 105.9 | Q3: 105.2 | R3: 105.9 | S3: 105 | T3: 105.8 | U3: 100.3 | V3: 105.4 | W3: 104.8 | X3: 104.1 | Y3: 103.2 | Z3: 102.9 | AA3: 103.5 | AB3: 104.3 | AC3: 103.7 | AD3: 104
A4: Rural+Urban | B4: 2013 | C4: January | D4: 108.4 | E4: 107.3 | F4: 110 | G4: 104.4 | H4: 105.1 | I4: 103.2 | J4: 102.2 | K4: 106 | L4: 106.2 | M4: 102.7 | N4: 104.9 | O4: 107.3 | P4: 105.6 | Q4: 105.1 | R4: 106.3 | S4: 105.5 | T4: 106.2 | U4: 100.3 | V4: 105.5 | W4: 104.8 | X4: 104 | Y4: 103.2 | Z4: 103.1 | AA4: 103.6 | AB4: 104.5 | AC4: 103.9 | AD4: 104.6
A5: Rural | B5: 2013 | C5: February | D5: 109.2 | E5: 108.7 | F5: 110.2 | G5: 105.4 | H5: 106.7 | I5: 104 | J5: 102.4 | K5: 105.9 | L5: 105.7 | M5: 103.1 | N5: 105.1 | O5: 107.7 | P5: 106.3 | Q5: 105.6 | R5: 107.1 | S5: 106.3 | T5: 107 | U5: NA | V5: 106.2 | W5: 105.2 | X5: 104.4 | Y5: 103.9 | Z5: 104 | AA5: 104.1 | AB5: 104.6 | AC5: 104.4 | AD5: 105.8
A6: Urban | B6: 2013 | C6: February | D6: 112.9 | E6: 112.9 | F6: 116.9 | G6: 104 | H6: 103.5 | I6: 103.1 | J6: 104.9 | K6: 104.1 | L6: 103.8 | M6: 102.3 | N6: 106 | O6: 109 | P6: 107.2 | Q6: 106 | R6: 106.6 | S6: 105.5 | T6: 106.4 | U6: 100.4 | V6: 105.7 | W6: 105.2 | X6: 104.7 | Y6: 104.4 | Z6: 103.3 | AA6: 103.7 | AB6: 104.3 | AC6: 104.3 | AD6: 104.7
A7: Rural+Urban | B7: 2013 | C7: February | D7: 110.4 | E7: 110.2 | F7: 112.8 | G7: 104.9 | H7: 105.5 | I7: 103.6 | J7: 103.2 | K7: 105.3 | L7: 105.1 | M7: 102.8 | N7: 105.5 | O7: 108.3 | P7: 106.6 | Q7: 105.7 | R7: 106.9 | S7: 106 | T7: 106.8 | U7: 100.4 | V7: 106 | W7: 105.2 | X7: 104.5 | Y7: 104.2 | Z7: 103.6 | AA7: 103.9 | AB7: 104.5 | AC7: 104.4 | AD7: 105.3
A8: Rural | B8: 2013 | C8: March | D8: 110.2 | E8: 108.8 | F8: 109.9 | G8: 105.6 | H8: 106.2 | I8: 105.7 | J8: 101.4 | K8: 105.7 | L8: 105 | M8: 103.3 | N8: 105.6 | O8: 108.2 | P8: 106.6 | Q8: 106.5 | R8: 107.6 | S8: 106.8 | T8: 107.5 | U8: NA | V8: 106.1 | W8: 105.6 | X8: 104.7 | Y8: 104.6 | Z8: 104 | AA8: 104.3 | AB8: 104.3 | AC8: 104.6 | AD8: 106
A9: Urban | B9: 2013 | C9: March | D9: 113.9 | E9: 111.4 | F9: 113.2 | G9: 104.3 | H9: 102.7 | I9: 104.9 | J9: 103.8 | K9: 103.5 | L9: 102.6 | M9: 102.4 | N9: 107 | O9: 109.8 | P9: 107.3 | Q9: 106.8 | R9: 107.2 | S9: 106 | T9: 107 | U9: 100.4 | V9: 106 | W9: 105.7 | X9: 105.2 | Y9: 105.5 | Z9: 103.5 | AA9: 103.8 | AB9: 104.2 | AC9: 104.9 | AD9: 105
A10: Rural+Urban | B10: 2013 | C10: March | D10: 111.4 | E10: 109.7 | F10: 111.2 | G10: 105.1 | H10: 104.9 | I10: 105.3 | J10: 102.2 | K10: 105 | L10: 104.2 | M10: 103 | N10: 106.2 | O10: 108.9 | P10: 106.9 | Q10: 106.6 | R10: 107.4 | S10: 106.5 | T10: 107.3 | U10: 100.4 | V10: 106.1 | W10: 105.6 | X10: 104.9 | Y10: 105.1 | Z10: 103.7 | AA10: 104 | AB10: 104.3 | AC10: 104.7 | AD10: 105.5
A11: Rural | B11: 2013 | C11: April | D11: 110.2 | E11: 109.5 | F11: 106.9 | G11: 106.3 | H11: 105.7 | I11: 108.3 | J11: 103.4 | K11: 105.7 | L11: 104.2 | M11: 103.2 | N11: 106.5 | O11: 108.8 | P11: 107.1 | Q11: 107.1 | R11: 108.1 | S11: 107.4 | T11: 108 | U11: NA | V11: 106.5 | W11: 106.1 | X11: 105.1 | Y11: 104.4 | Z11: 104.5 | AA11: 104.8 | AB11: 102.7 | AC11: 104.6 | AD11: 106.4
A12: Urban | B12: 2013 | C12: April | D12: 114.6 | E12: 113.4 | F12: 106 | G12: 104.7 | H12: 102.1 | I12: 109.5 | J12: 109.7 | K12: 104.6 | L12: 102 | M12: 103.5 | N12: 108.2 | O12: 110.6 | P12: 108.8 | Q12: 108.5 | R12: 107.9 | S12: 106.4 | T12: 107.7 | U12: 100.5 | V12: 106.4 | W12: 106.5 | X12: 105.7 | Y12: 105 | Z12: 104 | AA12: 105.2 | AB12: 103.2 | AC12: 105.1 | AD12: 105.7
A13: Rural+Urban | B13: 2013 | C13: April | D13: 111.6 | E13: 110.9 | F13: 106.6 | G13: 105.7 | H13: 104.4 | I13: 108.9 | J13: 105.5 | K13: 105.3 | L13: 103.5 | M13: 103.3 | N13: 107.2 | O13: 109.6 | P13: 107.7 | Q13: 107.5 | R13: 108 | S13: 107 | T13: 107.9 | U13: 100.5 | V13: 106.5 | W13: 106.3 | X13: 105.3 | Y13: 104.7 | Z13: 104.2 | AA13: 105 | AB13: 102.9 | AC13: 104.8 | AD13: 106.1
... A259: Rural+Urban | B259: 2020 | C259: March | D259: 145.1 | E259: 167 | F259: 148.1 | G259: 151.5 | H259: 131.2 | I259: 142.5 | J259: 157.3 | K259: 141.1 | L259: 113.2 | M259: 153.2 | N259: 136.7 | O259: 159.6 | P259: 148.9 | Q259: 171.2 | R259: 151.2 | S259: 141.9 | T259: 149.8 | U259: 154.5 | V259: 148.9 | W259: 146.4 | X259: 152.3 | Y259: 129.9 | Z259: 143.7 | AA259: 156.1 | AB259: 145.2 | AC259: 143.8 | AD259: 148.6
A260: Rural | B260: 2020 | C260: April | D260: 147.2 | F260: 146.9 | G260: 155.6 | H260: 137.1 | I260: 147.3 | J260: 162.7 | K260: 150.2 | L260: 119.8 | M260: 158.7 | N260: 139.2 | P260: 150.1 | U260: NA | V260: 148.4 | X260: 154.3
A261: Urban | B261: 2020 | C261: April | D261: 151.8 | F261: 151.9 | G261: 155.5 | H261: 131.6 | I261: 152.9 | J261: 180 | K261: 150.8 | L261: 121.2 | M261: 154 | N261: 133.5 | P261: 153.5 | U261: 155.6 | V261: 137.1 | X261: 144.8
A262: Rural+Urban | B262: 2020 | C262: April | D262: 148.7 | F262: 148.8 | G262: 155.6 | H262: 135.1 | I262: 149.9 | J262: 168.6 | K262: 150.4 | L262: 120.3 | M262: 157.1 | N262: 136.8 | P262: 151.4 | U262: 155.6 | V262: 144.1 | X262: 150.7
A263: Rural | B263: 2020 | C263: May | U263: NA
A264: Urban | B264: 2020 | C264: May | U264: NA
A265: Rural+Urban | B265: 2020 | C265: May | U265: NA
A266: Rural | B266: 2020 | C266: June | D266: 148.2 | E266: 190.3 | F266: 149.4 | G266: 153.3 | H266: 138.2 | I266: 143.2 | J266: 148.9 | K266: 150.3 | L266: 113.2 | M266: 159.8 | N266: 142.1 | O266: 161.8 | P266: 152.3 | Q266: 182.4 | R266: 154.7 | S266: 150 | T266: 154.1 | U266: NA | V266: 144.9 | W266: 151.7 | X266: 158.2 | Y266: 141.4 | Z266: 153.2 | AA266: 161.8 | AB266: 151.2 | AC266: 151.7 | AD266: 152.7
A267: Urban | B267: 2020 | C267: June | D267: 152.7 | E267: 197 | F267: 154.6 | G267: 153.4 | H267: 132.9 | I267: 151.8 | J267: 171.2 | K267: 152 | L267: 116.3 | M267: 158.8 | N267: 135.6 | O267: 161.7 | P267: 157 | Q267: 186.7 | R267: 149.1 | S267: 136.6 | T267: 147.2 | U267: 154.7 | V267: 137.1 | W267: 140.4 | X267: 148.1 | Y267: 129.3 | Z267: 144.5 | AA267: 152.5 | AB267: 152.2 | AC267: 142 | AD267: 150.8
A268: Rural+Urban | B268: 2020 | C268: June | D268: 149.6 | E268: 192.7 | F268: 151.4 | G268: 153.3 | H268: 136.3 | I268: 147.2 | J268: 156.5 | K268: 150.9 | L268: 114.2 | M268: 159.5 | N268: 139.4 | O268: 161.8 | P268: 154 | Q268: 183.5 | R268: 152.5 | S268: 144.4 | T268: 151.4 | U268: 154.7 | V268: 141.9 | W268: 146.4 | X268: 154.4 | Y268: 135 | Z268: 148.3 | AA268: 156.4 | AB268: 151.6 | AC268: 147 | AD268: 151.8
A269: Rural | B269: 2020 | C269: July | D269: 148.2 | E269: 190.3 | F269: 149.4 | G269: 153.3 | H269: 138.2 | I269: 143.2 | J269: 148.9 | K269: 150.3 | L269: 113.2 | M269: 159.8 | N269: 142.1 | O269: 161.8 | P269: 152.3 | Q269: 182.4 | R269: 154.7 | S269: 150 | T269: 154.1 | U269: NA | V269: 144.9 | W269: 151.7 | X269: 158.2 | Y269: 141.4 | Z269: 153.2 | AA269: 161.8 | AB269: 151.2 | AC269: 151.7 | AD269: 152.7
A270: Urban | B270: 2020 | C270: July | D270: 152.7 | E270: 197 | F270: 154.6 | G270: 153.4 | H270: 132.9 | I270: 151.8 | J270: 171.2 | K270: 152 | L270: 116.3 | M270: 158.8 | N270: 135.6 | O270: 161.7 | P270: 157 | Q270: 186.7 | R270: 149.1 | S270: 136.6 | T270: 147.2 | U270: 154.7 | V270: 137.1 | W270: 140.4 | X270: 148.1 | Y270: 129.3 | Z270: 144.5 | AA270: 152.5 | AB270: 152.2 | AC270: 142 | AD270: 150.8
A271: Rural+Urban | B271: 2020 | C271: July | D271: 149.6 | E271: 192.7 | F271: 151.4 | G271: 153.3 | H271: 136.3 | I271: 147.2 | J271: 156.5 | K271: 150.9 | L271: 114.2 | M271: 159.5 | N271: 139.4 | O271: 161.8 | P271: 154 | Q271: 183.5 | R271: 152.5 | S271: 144.4 | T271: 151.4 | U271: 154.7 | V271: 141.9 | W271: 146.4 | X271: 154.4 | Y271: 135 | Z271: 148.3 | AA271: 156.4 | AB271: 151.6 | AC271: 147 | AD271: 151.8
A272: Rural | B272: 2020 | C272: August | D272: 147.6 | E272: 187.2 | F272: 148.4 | G272: 153.3 | H272: 139.8 | I272: 146.9 | J272: 171 | K272: 149.9 | L272: 114.2 | M272: 160 | N272: 143.5 | O272: 161.5 | P272: 155.3 | Q272: 180.9 | R272: 155.1 | S272: 149.3 | T272: 154.3 | U272: NA | V272: 145.8 | W272: 151.9 | X272: 158.8 | Y272: 143.6 | Z272: 152.2 | AA272: 162.7 | AB272: 153.6 | AC272: 153 | AD272: 154.7
A273: Urban | B273: 2020 | C273: August | D273: 151.6 | E273: 197.8 | F273: 154.5 | G273: 153.4 | H273: 133.4 | I273: 154.5 | J273: 191.9 | K273: 151.3 | L273: 116.8 | M273: 160 | N273: 136.5 | O273: 163.3 | P273: 159.9 | Q273: 187.2 | R273: 150 | S273: 135.2 | T273: 147.8 | U273: 155.5 | V273: 138.3 | W273: 144.5 | X273: 148.7 | Y273: 133.9 | Z273: 141.2 | AA273: 155.5 | AB273: 155.2 | AC273: 144.8 | AD273: 152.9
A274: Rural+Urban | B274: 2020 | C274: August | D274: 148.9 | E274: 190.9 | F274: 150.8 | G274: 153.3 | H274: 137.4 | I274: 150.4 | J274: 178.1 | K274: 150.4 | L274: 115.1 | M274: 160 | N274: 140.6 | O274: 162.3 | P274: 157 | Q274: 182.6 | R274: 153.1 | S274: 143.4 | T274: 151.7 | U274: 155.5 | V274: 143 | W274: 148.4 | X274: 155 | Y274: 138.5 | Z274: 146 | AA274: 158.5 | AB274: 154.3 | AC274: 149 | AD274: 153.9
A275: Rural | B275: 2020 | C275: September | D275: 146.9 | E275: 183.9 | F275: 149.5 | G275: 153.4 | H275: 140.4 | I275: 147 | J275: 178.8 | K275: 149.3 | L275: 115.1 | M275: 160 | N275: 145.4 | O275: 161.6 | P275: 156.1 | Q275: 182.9 | R275: 155.4 | S275: 149.9 | T275: 154.6 | U275: NA | V275: 146.4 | W275: 151.6 | X275: 159.1 | Y275: 144.6 | Z275: 152.8 | AA275: 161.1 | AB275: 157.4 | AC275: 153.7 | AD275: 155.4
A276: Urban | B276: 2020 | C276: September | D276: 151.5 | E276: 193.1 | F276: 157.3 | G276: 153.9 | H276: 134.4 | I276: 155.4 | J276: 202 | K276: 150.8 | L276: 118.9 | M276: 160.9 | N276: 137.7 | O276: 164.4 | P276: 161.3 | Q276: 188.7 | R276: 150.2 | S276: 136.3 | T276: 148.1 | U276: 156.3 | V276: 137.2 | W276: 145.4 | X276: 150 | Y276: 135.1 | Z276: 141.8 | AA276: 154.9 | AB276: 159.8 | AC276: 146 | AD276: 154
A277: Rural+Urban | B277: 2020 | C277: September | D277: 148.4 | E277: 187.1 | F277: 152.5 | G277: 153.6 | H277: 138.2 | I277: 150.9 | J277: 186.7 | K277: 149.8 | L277: 116.4 | M277: 160.3 | N277: 142.2 | O277: 162.9 | P277: 158 | Q277: 184.4 | R277: 153.4 | S277: 144.3 | T277: 152 | U277: 156.3 | V277: 142.9 | W277: 148.7 | X277: 155.6 | Y277: 139.6 | Z277: 146.6 | AA277: 157.5 | AB277: 158.4 | AC277: 150 | AD277: 154.7
... A373: Rural+Urban | B373: 2023 | C373: May | D373: 173.7 | E373: 214.3 | F373: 173.2 | G373: 179.5 | H373: 170 | I373: 172.2 | J373: 161 | K373: 175.6 | L373: 122.7 | M373: 218 | N373: 173.4 | O373: 194.2 | P373: 179.1 | Q373: 201 | R373: 187.3 | S373: 179.7 | T373: 186.2 | U373: 175.6 | V373: 182.8 | W373: 175.2 | X373: 185.7 | Y373: 164.8 | Z373: 171.2 | AA373: 177.1 | AB373: 185.2 | AC373: 175.7 | AD373: 179.1

Sheet Working Data
A1: Sector | B1: Year | C1: Month | D1: Cereals and products | E1: Meat and fish | F1: Egg | G1: Milk and products | H1: Oils and fats | I1: Fruits | J1: Vegetables | K1: Pulses and products | L1: Sugar and Confectionery | M1: Spices | N1: Non-alcoholic beverages | O1: Prepared meals, snacks, sweets etc. | P1: Food and beverages | Q1: Pan, tobacco and intoxicants | R1: Clothing | S1: Footwear | T1: Clothing and footwear | U1: Housing | V1: Fuel and light | W1: Household goods and services | X1: Health | Y1: Transport and communication | Z1: Recreation and amusement | AA1: Education | AB1: Personal care and effects | AC1: Miscellaneous | AD1: General index
A2: Rural | B2: 2013 | C2: January | D2: 107.5 | E2: 106.3 | F2: 108.1 | G2: 104.9 | H2: 106.1 | I2: 103.9 | J2: 101.9 | K2: 106.1 | L2: 106.8 | M2: 103.1 | N2: 104.8 | O2: 106.7 | P2: 105.5 | Q2: 105.1 | R2: 106.5 | S2: 105.8 | T2: 106.4 | U2: NA | V2: 105.5 | W2: 104.8 | X2: 104 | Y2: 103.3 | Z2: 103.4 | AA2: 103.8 | AB2: 104.7 | AC2: 104 | AD2: 105.1
A3: Urban | B3: 2013 | C3: January | D3: 110.5 | E3: 109.1 | F3: 113 | G3: 103.6 | H3: 103.4 | I3: 102.3 | J3: 102.9 | K3: 105.8 | L3: 105.1 | M3: 101.8 | N3: 105.1 | O3: 107.9 | P3: 105.9 | Q3: 105.2 | R3: 105.9 | S3: 105 | T3: 105.8 | U3: 100.3 | V3: 105.4 | W3: 104.8 | X3: 104.1 | Y3: 103.2 | Z3: 102.9 | AA3: 103.5 | AB3: 104.3 | AC3: 103.7 | AD3: 104
A4: Rural+Urban | B4: 2013 | C4: January | D4: 108.4 | E4: 107.3 | F4: 110 | G4: 104.4 | H4: 105.1 | I4: 103.2 | J4: 102.2 | K4: 106 | L4: 106.2 | M4: 102.7 | N4: 104.9 | O4: 107.3 | P4: 105.6 | Q4: 105.1 | R4: 106.3 | S4: 105.5 | T4: 106.2 | U4: 100.3 | V4: 105.5 | W4: 104.8 | X4: 104 | Y4: 103.2 | Z4: 103.1 | AA4: 103.6 | AB4: 104.5 | AC4: 103.9 | AD4: 104.6
A5: Rural | B5: 2013 | C5: February | D5: 109.2 | E5: 108.7 | F5: 110.2 | G5: 105.4 | H5: 106.7 | I5: 104 | J5: 102.4 | K5: 105.9 | L5: 105.7 | M5: 103.1 | N5: 105.1 | O5: 107.7 | P5: 106.3 | Q5: 105.6 | R5: 107.1 | S5: 106.3 | T5: 107 | U5: NA | V5: 106.2 | W5: 105.2 | X5: 104.4 | Y5: 103.9 | Z5: 104 | AA5: 104.1 | AB5: 104.6 | AC5: 104.4 | AD5: 105.8
A6: Urban | B6: 2013 | C6: February | D6: 112.9 | E6: 112.9 | F6: 116.9 | G6: 104 | H6: 103.5 | I6: 103.1 | J6: 104.9 | K6: 104.1 | L6: 103.8 | M6: 102.3 | N6: 106 | O6: 109 | P6: 107.2 | Q6: 106 | R6: 106.6 | S6: 105.5 | T6: 106.4 | U6: 100.4 | V6: 105.7 | W6: 105.2 | X6: 104.7 | Y6: 104.4 | Z6: 103.3 | AA6: 103.7 | AB6: 104.3 | AC6: 104.3 | AD6: 104.7
A7: Rural+Urban | B7: 2013 | C7: February | D7: 110.4 | E7: 110.2 | F7: 112.8 | G7: 104.9 | H7: 105.5 | I7: 103.6 | J7: 103.2 | K7: 105.3 | L7: 105.1 | M7: 102.8 | N7: 105.5 | O7: 108.3 | P7: 106.6 | Q7: 105.7 | R7: 106.9 | S7: 106 | T7: 106.8 | U7: 100.4 | V7: 106 | W7: 105.2 | X7: 104.5 | Y7: 104.2 | Z7: 103.6 | AA7: 103.9 | AB7: 104.5 | AC7: 104.4 | AD7: 105.3
A8: Rural | B8: 2013 | C8: March | D8: 110.2 | E8: 108.8 | F8: 109.9 | G8: 105.6 | H8: 106.2 | I8: 105.7 | J8: 101.4 | K8: 105.7 | L8: 105 | M8: 103.3 | N8: 105.6 | O8: 108.2 | P8: 106.6 | Q8: 106.5 | R8: 107.6 | S8: 106.8 | T8: 107.5 | U8: NA | V8: 106.1 | W8: 105.6 | X8: 104.7 | Y8: 104.6 | Z8: 104 | AA8: 104.3 | AB8: 104.3 | AC8: 104.6 | AD8: 106
A9: Urban | B9: 2013 | C9: March | D9: 113.9 | E9: 111.4 | F9: 113.2 | G9: 104.3 | H9: 102.7 | I9: 104.9 | J9: 103.8 | K9: 103.5 | L9: 102.6 | M9: 102.4 | N9: 107 | O9: 109.8 | P9: 107.3 | Q9: 106.8 | R9: 107.2 | S9: 106 | T9: 107 | U9: 100.4 | V9: 106 | W9: 105.7 | X9: 105.2 | Y9: 105.5 | Z9: 103.5 | AA9: 103.8 | AB9: 104.2 | AC9: 104.9 | AD9: 105
A10: Rural+Urban | B10: 2013 | C10: March | D10: 111.4 | E10: 109.7 | F10: 111.2 | G10: 105.1 | H10: 104.9 | I10: 105.3 | J10: 102.2 | K10: 105 | L10: 104.2 | M10: 103 | N10: 106.2 | O10: 108.9 | P10: 106.9 | Q10: 106.6 | R10: 107.4 | S10: 106.5 | T10: 107.3 | U10: 100.4 | V10: 106.1 | W10: 105.6 | X10: 104.9 | Y10: 105.1 | Z10: 103.7 | AA10: 104 | AB10: 104.3 | AC10: 104.7 | AD10: 105.5
A11: Rural | B11: 2013 | C11: April | D11: 110.2 | E11: 109.5 | F11: 106.9 | G11: 106.3 | H11: 105.7 | I11: 108.3 | J11: 103.4 | K11: 105.7 | L11: 104.2 | M11: 103.2 | N11: 106.5 | O11: 108.8 | P11: 107.1 | Q11: 107.1 | R11: 108.1 | S11: 107.4 | T11: 108 | U11: NA | V11: 106.5 | W11: 106.1 | X11: 105.1 | Y11: 104.4 | Z11: 104.5 | AA11: 104.8 | AB11: 102.7 | AC11: 104.6 | AD11: 106.4
A12: Urban | B12: 2013 | C12: April | D12: 114.6 | E12: 113.4 | F12: 106 | G12: 104.7 | H12: 102.1 | I12: 109.5 | J12: 109.7 | K12: 104.6 | L12: 102 | M12: 103.5 | N12: 108.2 | O12: 110.6 | P12: 108.8 | Q12: 108.5 | R12: 107.9 | S12: 106.4 | T12: 107.7 | U12: 100.5 | V12: 106.4 | W12: 106.5 | X12: 105.7 | Y12: 105 | Z12: 104 | AA12: 105.2 | AB12: 103.2 | AC12: 105.1 | AD12: 105.7
A13: Rural+Urban | B13: 2013 | C13: April | D13: 111.6 | E13: 110.9 | F13: 106.6 | G13: 105.7 | H13: 104.4 | I13: 108.9 | J13: 105.5 | K13: 105.3 | L13: 103.5 | M13: 103.3 | N13: 107.2 | O13: 109.6 | P13: 107.7 | Q13: 107.5 | R13: 108 | S13: 107 | T13: 107.9 | U13: 100.5 | V13: 106.5 | W13: 106.3 | X13: 105.3 | Y13: 104.7 | Z13: 104.2 | AA13: 105 | AB13: 102.9 | AC13: 104.8 | AD13: 106.1
... A27: Urban | B27: 2013 | C27: September | D27: 118.6 | E27: 119.1 | F27: 113.2 | G27: 109.6 | H27: 101.7 | I27: 103.2 | J27: 174.3 | K27: 105.1 | L27: 100.8 | M27: 109.1 | N27: 111.1 | O27: 115.4 | P27: 119.2 | Q27: 112.9 | R27: 111.4 | S27: 109 | T27: 111.1 | U27: 109.7 | V27: 109.5 | W27: 109.6 | X27: 107.9 | Y27: 110.4 | Z27: 107.4 | AA27: 111.2 | AB27: 106.9 | AC27: 109.4 | AD27: 113.2
A28: Rural+Urban | B28: 2013 | C28: September | D28: 116.4 | E28: 116.9 | F28: 112.3 | G28: 110.5 | H28: 105.3 | I28: 107.3 | J28: 160.9 | K28: 107.1 | L28: 103.1 | M28: 108.3 | N28: 110.7 | O28: 114.6 | P28: 118.3 | Q28: 112 | R28: 112.2 | S28: 110.4 | T28: 111.9 | U28: 109.7 | V28: 110.5 | W28: 109.6 | X28: 108.1 | Y28: 109.9 | Z28: 107.5 | AA28: 110.6 | AB28: 106.8 | AC28: 109 | AD28: 113.7
A29: Rural | B29: 2013 | C29: October | D29: 116.3 | E29: 115.4 | F29: 112.6 | G29: 111.7 | H29: 107.7 | I29: 113.2 | J29: 164.9 | K29: 108.3 | L29: 103.9 | M29: 108.2 | N29: 111.1 | O29: 114.9 | P29: 119.8 | Q29: 112.2 | R29: 113.6 | S29: 112.3 | T29: 113.4 | U29: NA | V29: 111.6 | W29: 110.4 | X29: 108.9 | Y29: 109.3 | Z29: 108.3 | AA29: 110.2 | AB29: 107.5 | AC29: 109.1 | AD29: 115.5
A30: Urban | B30: 2013 | C30: October | D30: 118.9 | E30: 118.1 | F30: 114.5 | G30: 110.4 | H30: 102.3 | I30: 106.2 | J30: 183.5 | K30: 105.3 | L30: 100.2 | M30: 109.6 | N30: 111.4 | O30: 116 | P30: 120.8 | Q30: 113.5 | R30: 112.5 | S30: 109.7 | T30: 112 | U30: 110.5 | V30: 109.7 | W30: 110.2 | X30: 108.2 | Y30: 109.7 | Z30: 108 | AA30: 111.3 | AB30: 107.3 | AC30: 109.4 | AD30: 114
A31: Rural+Urban | B31: 2013 | C31: October | D31: 117.1 | E31: 116.3 | F31: 113.3 | G31: 111.2 | H31: 105.7 | I31: 109.9 | J31: 171.2 | K31: 107.3 | L31: 102.7 | M31: 108.7 | N31: 111.2 | O31: 115.4 | P31: 120.2 | Q31: 112.5 | R31: 113.2 | S31: 111.2 | T31: 112.8 | U31: 110.5 | V31: 110.9 | W31: 110.3 | X31: 108.6 | Y31: 109.5 | Z31: 108.1 | AA31: 110.8 | AB31: 107.4 | AC31: 109.2 | AD31: 114.8
A32: Rural | B32: 2013 | C32: November | D32: 117.3 | E32: 114.9 | F32: 116.2 | G32: 112.8 | H32: 108.9 | I32: 116.6 | J32: 178.1 | K32: 109.1 | L32: 103.6 | M32: 109 | N32: 111.8 | O32: 116 | P32: 122.5 | Q32: 112.8 | R32: 114.6 | S32: 113.1 | T32: 114.4 | U32: NA | V32: 112.6 | W32: 111.3 | X32: 109.7 | Y32: 109.6 | Z32: 108.7 | AA32: 111 | AB32: 108.2 | AC32: 109.8 | AD32: 117.4
A33: Urban | B33: 2013 | C33: November | D33: 119.8 | E33: 116.3 | F33: 122.6 | G33: 112 | H33: 103.2 | I33: 110 | J33: 192.8 | K33: 106.3 | L33: 99.5 | M33: 110.3 | N33: 111.8 | O33: 117.1 | P33: 122.9 | Q33: 114.1 | R33: 113.5 | S33: 110.3 | T33: 113 | U33: 111.1 | V33: 110 | W33: 110.9 | X33: 108.6 | Y33: 109.5 | Z33: 108.5 | AA33: 111.3 | AB33: 107.9 | AC33: 109.6 | AD33: 115
A34: Rural+Urban | B34: 2013 | C34: November | D34: 118.1 | E34: 115.4 | F34: 118.7 | G34: 112.5 | H34: 106.8 | I34: 113.5 | J34: 183.1 | K34: 108.2 | L34: 102.2 | M34: 109.4 | N34: 111.8 | O34: 116.5 | P34: 122.6 | Q34: 113.1 | R34: 114.2 | S34: 111.9 | T34: 113.8 | U34: 111.1 | V34: 111.6 | W34: 111.1 | X34: 109.3 | Y34: 109.5 | Z34: 108.6 | AA34: 111.2 | AB34: 108.1 | AC34: 109.7 | AD34: 116.3
A35: Rural | B35: 2013 | C35: December | D35: 118.4 | E35: 115.9 | F35: 120.4 | G35: 113.8 | H35: 109.5 | I35: 115.5 | J35: 145.7 | K35: 109.5 | L35: 102.9 | M35: 109.8 | N35: 112.1 | O35: 116.8 | P35: 118.7 | Q35: 113.6 | R35: 115.8 | S35: 114 | T35: 115.5 | U35: NA | V35: 112.8 | W35: 112.1 | X35: 110.1 | Y35: 109.9 | Z35: 109.2 | AA35: 111.6 | AB35: 108.1 | AC35: 110.1 | AD35: 115.5
A36: Urban | B36: 2013 | C36: December | D36: 120.5 | E36: 118.1 | F36: 128.5 | G36: 112.8 | H36: 103.4 | I36: 110.7 | J36: 144.8 | K36: 107.1 | L36: 98.6 | M36: 111.9 | N36: 112.1 | O36: 118.1 | P36: 117.8 | Q36: 115 | R36: 114.2 | S36: 110.9 | T36: 113.7 | U36: 110.7 | V36: 110.4 | W36: 111.3 | X36: 109 | Y36: 109.7 | Z36: 108.9 | AA36: 111.4 | AB36: 107.7 | AC36: 109.8 | AD36: 113.3
A37: Rural+Urban | B37: 2013 | C37: December | D37: 119.1 | E37: 116.7 | F37: 123.5 | G37: 113.4 | H37: 107.3 | I37: 113.3 | J37: 145.4 | K37: 108.7 | L37: 101.5 | M37: 110.5 | N37: 112.1 | O37: 117.4 | P37: 118.4 | Q37: 114 | R37: 115.2 | S37: 112.7 | T37: 114.8 | U37: 110.7 | V37: 111.9 | W37: 111.7 | X37: 109.7 | Y37: 109.8 | Z37: 109 | AA37: 111.5 | AB37: 107.9 | AC37: 110 | AD37: 114.5
A38: Rural | B38: 2014 | C38: January | D38: 118.9 | E38: 117.1 | F38: 120.5 | G38: 114.4 | H38: 109 | I38: 115.5 | J38: 123.9 | K38: 109.6 | L38: 101.8 | M38: 110.2 | N38: 112.4 | O38: 117.3 | P38: 116 | Q38: 114 | R38: 116.5 | S38: 114.5 | T38: 116.2 | U38: NA | V38: 113 | W38: 112.6 | X38: 110.6 | Y38: 110.5 | Z38: 109.6 | AA38: 111.8 | AB38: 108.3 | AC38: 110.6 | AD38: 114.2
A39: Urban | B39: 2014 | C39: January | D39: 121.2 | E39: 122 | F39: 129.9 | G39: 113.6 | H39: 102.9 | I39: 112.1 | J39: 118.9 | K39: 107.5 | L39: 96.9 | M39: 112.7 | N39: 112.1 | O39: 119 | P39: 115.5 | Q39: 115.7 | R39: 114.8 | S39: 111.3 | T39: 114.3 | U39: 111.6 | V39: 111 | W39: 111.9 | X39: 109.7 | Y39: 110.8 | Z39: 109.8 | AA39: 111.5 | AB39: 108 | AC39: 110.5 | AD39: 112.9
A40: Rural+Urban | B40: 2014 | C40: January | D40: 119.6 | E40: 118.8 | F40: 124.1 | G40: 114.1 | H40: 106.8 | I40: 113.9 | J40: 122.2 | K40: 108.9 | L40: 100.2 | M40: 111 | N40: 112.3 | O40: 118.1 | P40: 115.8 | Q40: 114.5 | R40: 115.8 | S40: 113.2 | T40: 115.4 | U40: 111.6 | V40: 112.2 | W40: 112.3 | X40: 110.3 | Y40: 110.7 | Z40: 109.7 | AA40: 111.6 | AB40: 108.2 | AC40: 110.6 | AD40: 113.6
... A367: Rural+Urban | B367: 2023 | C367: May | D367: 173.7 | E367: 214.3 | F367: 173.2 | G367: 179.5 | H367: 170 | I367: 172.2 | J367: 161 | K367: 175.6 | L367: 122.7 | M367: 218 | N367: 173.4 | O367: 194.2 | P367: 179.1 | Q367: 201 | R367: 187.3 | S367: 179.7 | T367: 186.2 | U367: 175.6 | V367: 182.8 | W367: 175.2 | X367: 185.7 | Y367: 164.8 | Z367: 171.2 | AA367: 177.1 | AB367: 185.2 | AC367: 175.7 | AD367: 179.1

Sheet Problems

Sheet 1 .Broader categories
A1: Sector | B1: Year | C1: Month | D1: Cereals and products | E1: Meat and fish | F1: Egg | G1: Milk and products | H1: Oils and fats | I1: Fruits | J1: Vegetables | K1: Pulses and products | L1: Sugar and Confectionery | M1: Spices | N1: Non-alcoholic beverages | O1: Prepared meals, snacks, sweets etc. | P1: Food and beverages | Q1: Pan, tobacco and intoxicants | R1: Clothing | S1: Footwear | T1: Clothing and footwear | U1: Housing | V1: Fuel and light | W1: Household goods and services | X1: Health | Y1: Transport and communication | Z1: Recreation and amusement | AA1: Education | AB1: Personal care and effects | AC1: Miscellaneous | AD1: General index
A2: Rural | B2: 2023 | C2: May | D2: 173.2 | E2: 211.5 | F2: 171 | G2: 179.6 | H2: 173.3 | I2: 169 | J2: 148.7 | K2: 174.9 | L2: 121.9 | M2: 221 | N2: 178.7 | O2: 191.1 | P2: 176.8 | Q2: 199.9 | R2: 191.2 | S2: 187.9 | T2: 190.8 | V2: 182.5 | W2: 179.8 | X2: 187.8 | Y2: 169.7 | Z2: 173.8 | AA2: 180.3 | AB2: 184.9 | AC2: 179.5 | AD2: 179.8
A3: Urban | B3: 2023 | C3: May | D3: 174.7 | E3: 219.4 | F3: 176.7 | G3: 179.4 | H3: 164.4 | I3: 175.8 | J3: 185 | K3: 176.9 | L3: 124.2 | M3: 211.9 | N3: 165.9 | O3: 197.7 | P3: 183.1 | Q3: 204.2 | R3: 181.3 | S3: 168.1 | T3: 179.3 | U3: 175.6 | V3: 183.4 | W3: 170.1 | X3: 182.2 | Y3: 160.4 | Z3: 169.2 | AA3: 174.8 | AB3: 185.6 | AC3: 171.6 | AD3: 178.2
A4: Rural+Urban | B4: 2023 | C4: May | D4: 173.7 | E4: 214.3 | F4: 173.2 | G4: 179.5 | H4: 170 | I4: 172.2 | J4: 161 | K4: 175.6 | L4: 122.7 | M4: 218 | N4: 173.4 | O4: 194.2 | P4: 179.1 | Q4: 201 | R4: 187.3 | S4: 179.7 | T4: 186.2 | U4: 175.6 | V4: 182.8 | W4: 175.2 | X4: 185.7 | Y4: 164.8 | Z4: 171.2 | AA4: 177.1 | AB4: 185.2 | AC4: 175.7 | AD4: 179.1
E9: Rural | F9: Urban | G9: Rural+Urban | H9: Broader categories | L9: Rural | M9: Urban | N9: Rural+Urban | O9: Rural % | P9: Urban % | Q9: Rural+Urban %
D10: Cereals and products | E10: =HLOOKUP(D10,$A$1:$AD$4,2,FALSE) -> 173.2 | F10: =HLOOKUP(D10,$A$1:$AD$4,3,FALSE) -> 174.7 | G10: =HLOOKUP(D10,$A$1:$AD$4,4,FALSE) -> 173.7 | H10: Food and Beverages | K10: Food and Beverages | L10: =SUMIF($H$10:$H$36,K10,$E$10:$E$36) -> 2290.7 | M10: =SUMIF($H$10:$H$36,K10,$F$10:$F$36) -> 2335.1 | N10: =SUMIF($H$10:$H$36,K10,$G$10:$G$36) -> 2306.9 | O10: =L10/$L$18 -> 0.50918023 | P10: =M10/$M$18 -> 0.50315672 | Q10: =N10/$N$18 -> 0.49563854
D11: Meat and fish | E11: 211.5 | F11: 219.4 | G11: 214.3 | H11: Food and Beverages | K11: Miscellaneous | L11: =SUMIF($H$10:$H$36,K11,$E$10:$E$36) -> 379.4 | M11: =SUMIF($H$10:$H$36,K11,$F$10:$F$36) -> 375.8 | N11: =SUMIF($H$10:$H$36,K11,$G$10:$G$36) -> 376.7 | O11: =L11/$L$18 -> 0.0843336 | P11: =M11/$M$18 -> 0.080975673 | Q11: =N11/$N$18 -> 0.08093417
D12: Egg | E12: 171 | F12: 176.7 | G12: 173.2 | H12: Food and Beverages | K12: Clothing and footwear | L12: =SUMIF($H$10:$H$36,K12,$E$10:$E$36) -> 569.9 | M12: =SUMIF($H$10:$H$36,K12,$F$10:$F$36) -> 528.7 | N12: =SUMIF($H$10:$H$36,K12,$G$10:$G$36) -> 553.2 | O12: =L12/$L$18 -> 0.12667823 | P12: =M12/$M$18 -> 0.11392187 | Q12: =N12/$N$18 -> 0.11885528
D13: Milk and products | E13: 179.6 | F13: 179.4 | G13: 179.5 | H13: Food and Beverages | K13: Housing and households | L13: =SUMIF($H$10:$H$36,K13,$E$10:$E$36) -> 362.3 | M13: =SUMIF($H$10:$H$36,K13,$F$10:$F$36) -> 529.1 | N13: =SUMIF($H$10:$H$36,K13,$G$10:$G$36) -> 533.6 | O13: =L13/$L$18 -> 0.080532586 | P13: =M13/$M$18 -> 0.11400806 | Q13: =N13/$N$18 -> 0.11464421
D14: Oils and fats | E14: 173.3 | F14: 164.4 | G14: 170 | H14: Food and Beverages | K14: Health | L14: =SUMIF($H$10:$H$36,K14,$E$10:$E$36) -> 372.7 | M14: =SUMIF($H$10:$H$36,K14,$F$10:$F$36) -> 367.8 | N14: =SUMIF($H$10:$H$36,K14,$G$10:$G$36) -> 370.9 | O14: =L14/$L$18 -> 0.082844314 | P14: =M14/$M$18 -> 0.079251869 | Q14: =N14/$N$18 -> 0.079688037
D15: Fruits | E15: 169 | F15: 175.8 | G15: 172.2 | H15: Food and Beverages | K15: Transport and communication | L15: =SUMIF($H$10:$H$36,K15,$E$10:$E$36) -> 169.7 | M15: =SUMIF($H$10:$H$36,K15,$F$10:$F$36) -> 160.4 | N15: =SUMIF($H$10:$H$36,K15,$G$10:$G$36) -> 164.8 | O15: =L15/$L$18 -> 0.03772117 | P15: =M15/$M$18 -> 0.034562262 | Q15: =N15/$N$18 -> 0.035407356
D16: Vegetables | E16: 148.7 | F16: 185 | G16: 161 | H16: Food and Beverages | K16: Education and recreation | L16: =SUMIF($H$10:$H$36,K16,$E$10:$E$36) -> 354.1 | M16: =SUMIF($H$10:$H$36,K16,$F$10:$F$36) -> 344 | N16: =SUMIF($H$10:$H$36,K16,$G$10:$G$36) -> 348.3 | O16: =L16/$L$18 -> 0.078709878 | P16: =M16/$M$18 -> 0.074123554 | Q16: =N16/$N$18 -> 0.074832417
D17: Pulses and products | E17: 174.9 | F17: 176.9 | G17: 175.6 | H17: Food and Beverages | K17: General index | L17: =SUMIF($H$10:$H$36,K17,$E$10:$E$36) -> 179.8 | M17: =SUMIF($H$10:$H$36,K17,$F$10:$F$36) -> 178.2 | N17: =SUMIF($H$10:$H$36,K17,$G$10:$G$36) -> 179.1
D18: Sugar and Confectionery | E18: 121.9 | F18: 124.2 | G18: 122.7 | H18: Food and Beverages | K18: Total | L18: =SUM(L10:L16) -> 4498.8 | M18: =SUM(M10:M16) -> 4640.9 | N18: =SUM(N10:N16) -> 4654.4 | O18: =L18/$L$18 -> 1 | P18: =M18/$M$18 -> 1 | Q18: =N18/$N$18 -> 1
D19: Spices | E19: 221 | F19: 211.9 | G19: 218 | H19: Food and Beverages
D20: Non-alcoholic beverages | E20: 178.7 | F20: 165.9 | G20: 173.4 | H20: Food and Beverages
D21: Prepared meals, snacks, sweets etc. | E21: 191.1 | F21: 197.7 | G21: 194.2 | H21: Food and Beverages
D22: Food and beverages | E22: 176.8 | F22: 183.1 | G22: 179.1 | H22: Food and Beverages
D23: Pan, tobacco and intoxicants | E23: 199.9 | F23: 204.2 | G23: 201 | H23: Miscellaneous
D24: Clothing | E24: 191.2 | F24: 181.3 | G24: 187.3 | H24: Clothing and footwear
D25: Footwear | E25: 187.9 | F25: 168.1 | G25: 179.7 | H25: Clothing and footwear
D26: Clothing and footwear | E26: 190.8 | F26: 179.3 | G26: 186.2 | H26: Clothing and footwear
D27: Housing | E27: 0 | F27: 175.6 | G27: 175.6 | H27: Housing and households
D28: Fuel and light | E28: 182.5 | F28: 183.4 | G28: 182.8 | H28: Housing and households
D29: Household goods and services | E29: 179.8 | F29: 170.1 | G29: 175.2 | H29: Housing and households
D30: Health | E30: 187.8 | F30: 182.2 | G30: 185.7 | H30: Health
... D36: General index | E36: 179.8 | F36: 178.2 | G36: 179.1 | H36: General index

Sheet 2 .Y-O-Y CPI
A1: Sector | B1: Year | C1: Month | D1: General index
A2: Rural | B2: 2017 | C2: January | D2: 132.4
A3: Urban | B3: 2017 | C3: January | D3: 127.8
A4: Rural+Urban | B4: 2017 | C4: January | D4: 130.3 | F4: Sector | G4: 2017 | H4: 2018 | I4: 2019 | J4: 2020 | K4: 2021 | L4: 2022 | M4: 2023
A5: Rural | B5: 2017 | C5: February | D5: 132.6 | F5: Rural | G5: =AVERAGEIFS($D$2:$D$223,$A$2:$A$223,$F5,$B$2:$B$223,G$4) -> 135.63333 | H5: =AVERAGEIFS($D$2:$D$223,$A$2:$A$223,$F5,$B$2:$B$223,H$4) -> 140.73333 | I5: =AVERAGEIFS($D$2:$D$223,$A$2:$A$223,$F5,$B$2:$B$223,I$4) -> 145.18182 | J5: =AVERAGEIFS($D$2:$D$223,$A$2:$A$223,$F5,$B$2:$B$223,J$4) -> 154.56 | K5: =AVERAGEIFS($D$2:$D$223,$A$2:$A$223,$F5,$B$2:$B$223,K$4) -> 162.03333 | L5: =AVERAGEIFS($D$2:$D$223,$A$2:$A$223,$F5,$B$2:$B$223,L$4) -> 173.125 | M5: =AVERAGEIFS($D$2:$D$223,$A$2:$A$223,$F5,$B$2:$B$223,M$4) -> 178.48
A6: Urban | B6: 2017 | C6: February | D6: 128.2 | F6: Urban | G6: =AVERAGEIFS($D$2:$D$223,$A$2:$A$223,$F6,$B$2:$B$223,G$4) -> 131.025 | H6: =AVERAGEIFS($D$2:$D$223,$A$2:$A$223,$F6,$B$2:$B$223,H$4) -> 136.5 | I6: =AVERAGEIFS($D$2:$D$223,$A$2:$A$223,$F6,$B$2:$B$223,I$4) -> 143.01818 | J6: =AVERAGEIFS($D$2:$D$223,$A$2:$A$223,$F6,$B$2:$B$223,J$4) -> 152.05 | K6: =AVERAGEIFS($D$2:$D$223,$A$2:$A$223,$F6,$B$2:$B$223,K$4) -> 160.75833 | L6: =AVERAGEIFS($D$2:$D$223,$A$2:$A$223,$F6,$B$2:$B$223,L$4) -> 170.95 | M6: =AVERAGEIFS($D$2:$D$223,$A$2:$A$223,$F6,$B$2:$B$223,M$4) -> 176.62
A7: Rural+Urban | B7: 2017 | C7: February | D7: 130.6 | F7: Rural+Urban | G7: =AVERAGEIFS($D$2:$D$223,$A$2:$A$223,$F7,$B$2:$B$223,G$4) -> 133.5 | H7: =AVERAGEIFS($D$2:$D$223,$A$2:$A$223,$F7,$B$2:$B$223,H$4) -> 138.775 | I7: =AVERAGEIFS($D$2:$D$223,$A$2:$A$223,$F7,$B$2:$B$223,I$4) -> 144.18182 | J7: =AVERAGEIFS($D$2:$D$223,$A$2:$A$223,$F7,$B$2:$B$223,J$4) -> 153.38 | K7: =AVERAGEIFS($D$2:$D$223,$A$2:$A$223,$F7,$B$2:$B$223,K$4) -> 161.45833 | L7: =AVERAGEIFS($D$2:$D$223,$A$2:$A$223,$F7,$B$2:$B$223,L$4) -> 172.15 | M7: =AVERAGEIFS($D$2:$D$223,$A$2:$A$223,$F7,$B$2:$B$223,M$4) -> 177.62
A8: Rural | B8: 2017 | C8: March | D8: 132.8
A9: Urban | B9: 2017 | C9: March | D9: 128.7
A10: Rural+Urban | B10: 2017 | C10: March | D10: 130.9
A11: Rural | B11: 2017 | C11: April | D11: 132.9
A12: Urban | B12: 2017 | C12: April | D12: 129.1 | F12: Sector | G12: 2017 | H12: 2018 | I12: 2019 | J12: 2020 | K12: 2021 | L12: 2022 | M12: 2023
A13: Rural+Urban | B13: 2017 | C13: April | D13: 131.1 | F13: Rural | H13: =(H5-G5)/G5 -> 0.037601376 | I13: =(I5-H5)/H5 -> 0.031609319 | J13: =(J5-I5)/I5 -> 0.064596118 | K13: =(K5-J5)/J5 -> 0.048352312 | L13: =(L5-K5)/K5 -> 0.068452993 | M13: =(M5-L5)/L5 -> 0.030931408
A14: Rural | B14: 2017 | C14: May | D14: 133.3 | F14: Urban | H14: =(H6-G6)/G6 -> 0.041785919 | I14: =(I6-H6)/H6 -> 0.047752248 | J14: =(J6-I6)/I6 -> 0.063151538 | K14: =(K6-J6)/J6 -> 0.057272827 | L14: =(L6-K6)/K6 -> 0.063397439 | M14: =(M6-L6)/L6 -> 0.033167593
A15: Urban | B15: 2017 | C15: May | D15: 129.3 | F15: Rural+Urban | H15: =(H7-G7)/G7 -> 0.039513109 | I15: =(I7-H7)/H7 -> 0.038961039 | J15: =(J7-I7)/I7 -> 0.063795712 | K15: =(K7-J7)/J7 -> 0.052668753 | L15: =(L7-K7)/K7 -> 0.066219355 | M15: =(M7-L7)/L7 -> 0.031774615
A16: Rural+Urban | B16: 2017 | C16: May | D16: 131.4
A17: Rural | B17: 2017 | C17: June | D17: 133.9
A18: Urban | B18: 2017 | C18: June | D18: 129.9
A19: Rural+Urban | B19: 2017 | C19: June | D19: 132
A20: Rural | B20: 2017 | C20: July | D20: 136.2
A21: Urban | B21: 2017 | C21: July | D21: 131.8
A22: Rural+Urban | B22: 2017 | C22: July | D22: 134.2
A23: Rural | B23: 2017 | C23: August | D23: 137.8
A24: Urban | B24: 2017 | C24: August | D24: 132.7
A25: Rural+Urban | B25: 2017 | C25: August | D25: 135.4
A26: Rural | B26: 2017 | C26: September | D26: 137.6
A27: Urban | B27: 2017 | C27: September | D27: 132.4
... A223: Rural+Urban | B223: 2023 | C223: May | D223: 179.1

Sheet 3 .Food Inflation
A1: Sector | B1: Year | C1: Month | D1: Cereals and products | E1: Meat and fish | F1: Egg | G1: Milk and products | H1: Oils and fats | I1: Fruits | J1: Vegetables | K1: Pulses and products | L1: Sugar and Confectionery | M1: Spices | N1: Non-alcoholic beverages | O1: Prepared meals, snacks, sweets etc. | P1: Food and beverages | Q1: Food buckts avg | R1: Food buckts avg2
A2: Rural | B2: 2013 | C2: January | D2: 107.5 | E2: 106.3 | F2: 108.1 | G2: 104.9 | H2: 106.1 | I2: 103.9 | J2: 101.9 | K2: 106.1 | L2: 106.8 | M2: 103.1 | N2: 104.8 | O2: 106.7 | P2: 105.5 | Q2: =AVERAGE(All_India_Index_Upto_April23__134[[#This Row],[Cereals and products]:[Food and beverages]]) -> 105.51538 | R2: =AVERAGE(All_India_Index_Upto_April23__134[[#This Row],[Cereals and products]:[Prepared meals, snacks, sweets etc.]]) -> 105.51667
A3: Urban | B3: 2013 | C3: January | D3: 110.5 | E3: 109.1 | F3: 113 | G3: 103.6 | H3: 103.4 | I3: 102.3 | J3: 102.9 | K3: 105.8 | L3: 105.1 | M3: 101.8 | N3: 105.1 | O3: 107.9 | P3: 105.9 | Q3: =AVERAGE(All_India_Index_Upto_April23__134[[#This Row],[Cereals and products]:[Food and beverages]]) -> 105.87692 | R3: =AVERAGE(All_India_Index_Upto_April23__134[[#This Row],[Cereals and products]:[Prepared meals, snacks, sweets etc.]]) -> 105.875
A4: Rural+Urban | B4: 2013 | C4: January | D4: 108.4 | E4: 107.3 | F4: 110 | G4: 104.4 | H4: 105.1 | I4: 103.2 | J4: 102.2 | K4: 106 | L4: 106.2 | M4: 102.7 | N4: 104.9 | O4: 107.3 | P4: 105.6 | Q4: =AVERAGE(All_India_Index_Upto_April23__134[[#This Row],[Cereals and products]:[Food and beverages]]) -> 105.63846 | R4: =AVERAGE(All_India_Index_Upto_April23__134[[#This Row],[Cereals and products]:[Prepared meals, snacks, sweets etc.]]) -> 105.64167
A5: Rural | B5: 2013 | C5: February | D5: 109.2 | E5: 108.7 | F5: 110.2 | G5: 105.4 | H5: 106.7 | I5: 104 | J5: 102.4 | K5: 105.9 | L5: 105.7 | M5: 103.1 | N5: 105.1 | O5: 107.7 | P5: 106.3 | Q5: =AVERAGE(All_India_Index_Upto_April23__134[[#This Row],[Cereals and products]:[Food and beverages]]) -> 106.18462 | R5: =AVERAGE(All_India_Index_Upto_April23__134[[#This Row],[Cereals and products]:[Prepared meals, snacks, sweets etc.]]) -> 106.175
A6: Urban | B6: 2013 | C6: February | D6: 112.9 | E6: 112.9 | F6: 116.9 | G6: 104 | H6: 103.5 | I6: 103.1 | J6: 104.9 | K6: 104.1 | L6: 103.8 | M6: 102.3 | N6: 106 | O6: 109 | P6: 107.2 | Q6: =AVERAGE(All_India_Index_Upto_April23__134[[#This Row],[Cereals and products]:[Food and beverages]]) -> 106.96923 | R6: =AVERAGE(All_India_Index_Upto_April23__134[[#This Row],[Cereals and products]:[Prepared meals, snacks, sweets etc.]]) -> 106.95
A7: Rural+Urban | B7: 2013 | C7: February | D7: 110.4 | E7: 110.2 | F7: 112.8 | G7: 104.9 | H7: 105.5 | I7: 103.6 | J7: 103.2 | K7: 105.3 | L7: 105.1 | M7: 102.8 | N7: 105.5 | O7: 108.3 | P7: 106.6 | Q7: =AVERAGE(All_India_Index_Upto_April23__134[[#This Row],[Cereals and products]:[Food and beverages]]) -> 106.47692 | R7: =AVERAGE(All_India_Index_Upto_April23__134[[#This Row],[Cereals and products]:[Prepared meals, snacks, sweets etc.]]) -> 106.46667
A8: Rural | B8: 2013 | C8: March | D8: 110.2 | E8: 108.8 | F8: 109.9 | G8: 105.6 | H8: 106.2 | I8: 105.7 | J8: 101.4 | K8: 105.7 | L8: 105 | M8: 103.3 | N8: 105.6 | O8: 108.2 | P8: 106.6 | Q8: =AVERAGE(All_India_Index_Upto_April23__134[[#This Row],[Cereals and products]:[Food and beverages]]) -> 106.32308 | R8: =AVERAGE(All_India_Index_Upto_April23__134[[#This Row],[Cereals and products]:[Prepared meals, snacks, sweets etc.]]) -> 106.3
A9: Urban | B9: 2013 | C9: March | D9: 113.9 | E9: 111.4 | F9: 113.2 | G9: 104.3 | H9: 102.7 | I9: 104.9 | J9: 103.8 | K9: 103.5 | L9: 102.6 | M9: 102.4 | N9: 107 | O9: 109.8 | P9: 107.3 | Q9: =AVERAGE(All_India_Index_Upto_April23__134[[#This Row],[Cereals and products]:[Food and beverages]]) -> 106.67692 | R9: =AVERAGE(All_India_Index_Upto_April23__134[[#This Row],[Cereals and products]:[Prepared meals, snacks, sweets etc.]]) -> 106.625
A10: Rural+Urban | B10: 2013 | C10: March | D10: 111.4 | E10: 109.7 | F10: 111.2 | G10: 105.1 | H10: 104.9 | I10: 105.3 | J10: 102.2 | K10: 105 | L10: 104.2 | M10: 103 | N10: 106.2 | O10: 108.9 | P10: 106.9 | Q10: =AVERAGE(All_India_Index_Upto_April23__134[[#This Row],[Cereals and products]:[Food and beverages]]) -> 106.46154 | R10: =AVERAGE(All_India_Index_Upto_April23__134[[#This Row],[Cereals and products]:[Prepared meals, snacks, sweets etc.]]) -> 106.425
A11: Rural | B11: 2013 | C11: April | D11: 110.2 | E11: 109.5 | F11: 106.9 | G11: 106.3 | H11: 105.7 | I11: 108.3 | J11: 103.4 | K11: 105.7 | L11: 104.2 | M11: 103.2 | N11: 106.5 | O11: 108.8 | P11: 107.1 | Q11: =AVERAGE(All_India_Index_Upto_April23__134[[#This Row],[Cereals and products]:[Food and beverages]]) -> 106.6 | R11: =AVERAGE(All_India_Index_Upto_April23__134[[#This Row],[Cereals and products]:[Prepared meals, snacks, sweets etc.]]) -> 106.55833
A12: Urban | B12: 2013 | C12: April | D12: 114.6 | E12: 113.4 | F12: 106 | G12: 104.7 | H12: 102.1 | I12: 109.5 | J12: 109.7 | K12: 104.6 | L12: 102 | M12: 103.5 | N12: 108.2 | O12: 110.6 | P12: 108.8 | Q12: =AVERAGE(All_India_Index_Upto_April23__134[[#This Row],[Cereals and products]:[Food and beverages]]) -> 107.51538 | R12: =AVERAGE(All_India_Index_Upto_April23__134[[#This Row],[Cereals and products]:[Prepared meals, snacks, sweets etc.]]) -> 107.40833
A13: Rural+Urban | B13: 2013 | C13: April | D13: 111.6 | E13: 110.9 | F13: 106.6 | G13: 105.7 | H13: 104.4 | I13: 108.9 | J13: 105.5 | K13: 105.3 | L13: 103.5 | M13: 103.3 | N13: 107.2 | O13: 109.6 | P13: 107.7 | Q13: =AVERAGE(All_India_Index_Upto_April23__134[[#This Row],[Cereals and products]:[Food and beverages]]) -> 106.93846 | R13: =AVERAGE(All_India_Index_Upto_April23__134[[#This Row],[Cereals and products]:[Prepared meals, snacks, sweets etc.]]) -> 106.875
... A367: Rural+Urban | B367: 2023 | C367: May | D367: 173.7 | E367: 214.3 | F367: 173.2 | G367: 179.5 | H367: 170 | I367: 172.2 | J367: 161 | K367: 175.6 | L367: 122.7 | M367: 218 | N367: 173.4 | O367: 194.2 | P367: 179.1 | Q367: =AVERAGE(All_India_Index_Upto_April23__134[[#This Row],[Cereals and products]:[Food and beverages]]) -> 177.45385 | R367: =AVERAGE(All_India_Index_Upto_April23__134[[#This Row],[Cereals and products]:[Prepared meals, snacks, sweets etc.]]) -> 177.31667
G370: Food_bucktes
B371: Rural | C371: Urban | D371: Rural+Urban | E371: Broader categories | G371: M-O-M | H371: Months | I371: Rural | J371: Urban | K371: Rural+Urban | L371: Inflation % | N371: Food Categries | O371: 44713 | P371: 45047 | Q371: Y-O_Y
A372: Cereals and products | B372: 173.2 | C372: 174.7 | D372: 173.7 | E372: Food and Beverages | G372: 2022 | H372: June | I372: =AVERAGEIFS(All_India_Index_Upto_April23__134[[#All],[Food buckts avg2]],All_India_Index_Upto_April23__134[[#All],[Year]],$G372,All_India_Index_Upto_April23__134[[#All],[Month]],$H372,All_India_Index_Upto_April23__134[[#All],[Sector]],I$371) -> 172.99167 | J372: =AVERAGEIFS(All_India_Index_Upto_April23__134[[#All],[Food buckts avg2]],All_India_Index_Upto_April23__134[[#All],[Year]],$G372,All_India_Index_Upto_April23__134[[#All],[Month]],$H372,All_India_Index_Upto_April23__134[[#All],[Sector]],J$371) -> 175.68333 | K372: =AVERAGEIFS(All_India_Index_Upto_April23__134[[#All],[Food buckts avg2]],All_India_Index_Upto_April23__134[[#All],[Year]],$G372,All_India_Index_Upto_April23__134[[#All],[Month]],$H372,All_India_Index_Upto_April23__134[[#All],[Sector]],K$371) -> 173.91667 | N372: Cereals and products | O372: {=AVERAGEIFS(cer_pro,months,"june",year,"2022",sector,"Rural+Urban")} -> 155 | P372: {=AVERAGEIFS(cer_pro,months,"may",year,"2023",sector,"Rural+Urban")} -> 173.7 | Q372: =(P372-O372)/O372 -> 0.12064516
A373: Meat and fish | B373: 211.5 | C373: 219.4 | D373: 214.3 | E373: Food and Beverages | G373: 2022 | H373: July | I373: =AVERAGEIFS(All_India_Index_Upto_April23__134[[#All],[Food buckts avg2]],All_India_Index_Upto_April23__134[[#All],[Year]],$G373,All_India_Index_Upto_April23__134[[#All],[Month]],$H373,All_India_Index_Upto_April23__134[[#All],[Sector]],I$371) -> 173.33333 | J373: =AVERAGEIFS(All_India_Index_Upto_April23__134[[#All],[Food buckts avg2]],All_India_Index_Upto_April23__134[[#All],[Year]],$G373,All_India_Index_Upto_April23__134[[#All],[Month]],$H373,All_India_Index_Upto_April23__134[[#All],[Sector]],J$371) -> 176.01667 | K373: =AVERAGEIFS(All_India_Index_Upto_April23__134[[#All],[Food buckts avg2]],All_India_Index_Upto_April23__134[[#All],[Year]],$G373,All_India_Index_Upto_April23__134[[#All],[Month]],$H373,All_India_Index_Upto_April23__134[[#All],[Sector]],K$371) -> 174.275 | L373: =(K373-K372)/K372*100 -> 0.20603737 | N373: Meat and fish | O373: {=AVERAGEIFS(meat_fish,months,"june",year,"2022",sector,"Rural+Urban")} -> 219.4 | P373: {=AVERAGEIFS(meat_fish,months,"May",year,"2023",sector,"Rural+Urban")} -> 214.3 | Q373: =(P373-O373)/O373 -> -0.023245214
A374: Egg | B374: 171 | C374: 176.7 | D374: 173.2 | E374: Food and Beverages | G374: 2022 | H374: August | I374: =AVERAGEIFS(All_India_Index_Upto_April23__134[[#All],[Food buckts avg2]],All_India_Index_Upto_April23__134[[#All],[Year]],$G374,All_India_Index_Upto_April23__134[[#All],[Month]],$H374,All_India_Index_Upto_April23__134[[#All],[Sector]],I$371) -> 173.49167 | J374: =AVERAGEIFS(All_India_Index_Upto_April23__134[[#All],[Food buckts avg2]],All_India_Index_Upto_April23__134[[#All],[Year]],$G374,All_India_Index_Upto_April23__134[[#All],[Month]],$H374,All_India_Index_Upto_April23__134[[#All],[Sector]],J$371) -> 176.10833 | K374: =AVERAGEIFS(All_India_Index_Upto_April23__134[[#All],[Food buckts avg2]],All_India_Index_Upto_April23__134[[#All],[Year]],$G374,All_India_Index_Upto_April23__134[[#All],[Month]],$H374,All_India_Index_Upto_April23__134[[#All],[Sector]],K$371) -> 174.40833 | L374: =(K374-K373)/K373*100 -> 0.076507436 | N374: Egg | O374: {=AVERAGEIFS(egg,months,"june",year,"2022",sector,"Rural+Urban")} -> 170.8 | P374: {=AVERAGEIFS(egg,months,"may",year,"2022",sector,"Rural+Urban")} -> 162.4 | Q374: =(P374-O374)/O374 -> -0.049180328
A375: Milk and products | B375: 179.6 | C375: 179.4 | D375: 179.5 | E375: Food and Beverages | G375: 2022 | H375: September | I375: =AVERAGEIFS(All_India_Index_Upto_April23__134[[#All],[Food buckts avg2]],All_India_Index_Upto_April23__134[[#All],[Year]],$G375,All_India_Index_Upto_April23__134[[#All],[Month]],$H375,All_India_Index_Upto_April23__134[[#All],[Sector]],I$371) -> 174.35833 | J375: =AVERAGEIFS(All_India_Index_Upto_April23__134[[#All],[Food buckts avg2]],All_India_Index_Upto_April23__134[[#All],[Year]],$G375,All_India_Index_Upto_April23__134[[#All],[Month]],$H375,All_India_Index_Upto_April23__134[[#All],[Sector]],J$371) -> 177.05 | K375: =AVERAGEIFS(All_India_Index_Upto_April23__134[[#All],[Food buckts avg2]],All_India_Index_Upto_April23__134[[#All],[Year]],$G375,All_India_Index_Upto_April23__134[[#All],[Month]],$H375,All_India_Index_Upto_April23__134[[#All],[Sector]],K$371) -> 175.25833 | L375: =(K375-K374)/K374*100 -> 0.48736203 | N375: Milk and products | O375: {=AVERAGEIFS(Milk_pro,months,"june",year,"2022",sector,"Rural+Urban")} -> 165.8 | P375: {=AVERAGEIFS(Milk_pro,months,"may",year,"2023",sector,"Rural+Urban")} -> 179.5 | Q375: =(P375-O375)/O375 -> 0.082629674
A376: Oils and fats | B376: 173.3 | C376: 164.4 | D376: 170 | E376: Food and Beverages | G376: 2022 | H376: October | I376: =AVERAGEIFS(All_India_Index_Upto_April23__134[[#All],[Food buckts avg2]],All_India_Index_Upto_April23__134[[#All],[Year]],$G376,All_India_Index_Upto_April23__134[[#All],[Month]],$H376,All_India_Index_Upto_April23__134[[#All],[Sector]],I$371) -> 175.59167 | J376: =AVERAGEIFS(All_India_Index_Upto_April23__134[[#All],[Food buckts avg2]],All_India_Index_Upto_April23__134[[#All],[Year]],$G376,All_India_Index_Upto_April23__134[[#All],[Month]],$H376,All_India_Index_Upto_April23__134[[#All],[Sector]],J$371) -> 178.25 | K376: =AVERAGEIFS(All_India_Index_Upto_April23__134[[#All],[Food buckts avg2]],All_India_Index_Upto_April23__134[[#All],[Year]],$G376,All_India_Index_Upto_April23__134[[#All],[Month]],$H376,All_India_Index_Upto_April23__134[[#All],[Sector]],K$371) -> 176.475 | L376: =(K376-K375)/K375*100 -> 0.6942133 | N376: Oils and fats | O376: {=AVERAGEIFS(oils_fts,months,"june",year,"2022",sector,"Rural+Urban")} -> 200.9 | P376: {=AVERAGEIFS(oils_fts,months,"may",year,"2023",sector,"Rural+Urban")} -> 170 | Q376: =(P376-O376)/O376 -> -0.15380786
A377: Fruits | B377: 169 | C377: 175.8 | D377: 172.2 | E377: Food and Beverages | G377: 2022 | H377: November | I377: =AVERAGEIFS(All_India_Index_Upto_April23__134[[#All],[Food buckts avg2]],All_India_Index_Upto_April23__134[[#All],[Year]],$G377,All_India_Index_Upto_April23__134[[#All],[Month]],$H377,All_India_Index_Upto_April23__134[[#All],[Sector]],I$371) -> 175.925 | J377: =AVERAGEIFS(All_India_Index_Upto_April23__134[[#All],[Food buckts avg2]],All_India_Index_Upto_April23__134[[#All],[Year]],$G377,All_India_Index_Upto_April23__134[[#All],[Month]],$H377,All_India_Index_Upto_April23__134[[#All],[Sector]],J$371) -> 177.75833 | K377: =AVERAGEIFS(All_India_Index_Upto_April23__134[[#All],[Food buckts avg2]],All_India_Index_Upto_April23__134[[#All],[Year]],$G377,All_India_Index_Upto_April23__134[[#All],[Month]],$H377,All_India_Index_Upto_April23__134[[#All],[Sector]],K$371) -> 176.54167 | L377: =(K377-K376)/K376*100 -> 0.037776833 | N377: Fruits | O377: {=AVERAGEIFS(fruits,months,"june",year,"2022",sector,"Rural+Urban")} -> 169.7 | P377: {=AVERAGEIFS(fruits,months,"may",year,"2023",sector,"Rural+Urban")} -> 172.2 | Q377: =(P377-O377)/O377 -> 0.01473188
A378: Vegetables | B378: 148.7 | C378: 185 | D378: 161 | E378: Food and Beverages | G378: 2022 | H378: December | I378: =AVERAGEIFS(All_India_Index_Upto_April23__134[[#All],[Food buckts avg2]],All_India_Index_Upto_April23__134[[#All],[Year]],$G378,All_India_Index_Upto_April23__134[[#All],[Month]],$H378,All_India_Index_Upto_April23__134[[#All],[Sector]],I$371) -> 175.225 | J378: =AVERAGEIFS(All_India_Index_Upto_April23__134[[#All],[Food buckts avg2]],All_India_Index_Upto_April23__134[[#All],[Year]],$G378,All_India_Index_Upto_April23__134[[#All],[Month]],$H378,All_India_Index_Upto_April23__134[[#All],[Sector]],J$371) -> 176.43333 | K378: =AVERAGEIFS(All_India_Index_Upto_April23__134[[#All],[Food buckts avg2]],All_India_Index_Upto_April23__134[[#All],[Year]],$G378,All_India_Index_Upto_April23__134[[#All],[Month]],$H378,All_India_Index_Upto_April23__134[[#All],[Sector]],K$371) -> 175.625 | L378: =(K378-K377)/K377*100 -> -0.51923531 | N378: Vegetables | O378: {=AVERAGEIFS(vegetables,months,"june",year,"2022",sector,"Rural+Urban")} -> 182.3 | P378: {=AVERAGEIFS(vegetables,months,"May",year,"2023",sector,"Rural+Urban")} -> 161 | Q378: =(P378-O378)/O378 -> -0.11684037
A379: Pulses and products | B379: 174.9 | C379: 176.9 | D379: 175.6 | E379: Food and Beverages | G379: 2023 | H379: January | I379: =AVERAGEIFS(All_India_Index_Upto_April23__134[[#All],[Food buckts avg2]],All_India_Index_Upto_April23__134[[#All],[Year]],$G379,All_India_Index_Upto_April23__134[[#All],[Month]],$H379,All_India_Index_Upto_April23__134[[#All],[Sector]],I$371) -> 175.68333 | J379: =AVERAGEIFS(All_India_Index_Upto_April23__134[[#All],[Food buckts avg2]],All_India_Index_Upto_April23__134[[#All],[Year]],$G379,All_India_Index_Upto_April23__134[[#All],[Month]],$H379,All_India_Index_Upto_April23__134[[#All],[Sector]],J$371) -> 177.55833 | K379: =AVERAGEIFS(All_India_Index_Upto_April23__134[[#All],[Food buckts avg2]],All_India_Index_Upto_April23__134[[#All],[Year]],$G379,All_India_Index_Upto_April23__134[[#All],[Month]],$H379,All_India_Index_Upto_April23__134[[#All],[Sector]],K$371) -> 176.33333 | L379: =(K379-K378)/K378*100 -> 0.40332147 | N379: Pulses and products | O379: {=AVERAGEIFS(Pulses_prod,months,"june",year,"2022",sector,"Rural+Urban")} -> 164.3 | P379: {=AVERAGEIFS(Pulses_prod,months,"may",year,"2023",sector,"Rural+Urban")} -> 175.6 | Q379: =(P379-O379)/O379 -> 0.068776628
A380: Sugar and Confectionery | B380: 121.9 | C380: 124.2 | D380: 122.7 | E380: Food and Beverages | G380: 2023 | H380: February | I380: =AVERAGEIFS(All_India_Index_Upto_April23__134[[#All],[Food buckts avg2]],All_India_Index_Upto_April23__134[[#All],[Year]],$G380,All_India_Index_Upto_April23__134[[#All],[Month]],$H380,All_India_Index_Upto_April23__134[[#All],[Sector]],I$371) -> 174.24167 | J380: =AVERAGEIFS(All_India_Index_Upto_April23__134[[#All],[Food buckts avg2]],All_India_Index_Upto_April23__134[[#All],[Year]],$G380,All_India_Index_Upto_April23__134[[#All],[Month]],$H380,All_India_Index_Upto_April23__134[[#All],[Sector]],J$371) -> 176.875 | K380: =AVERAGEIFS(All_India_Index_Upto_April23__134[[#All],[Food buckts avg2]],All_India_Index_Upto_April23__134[[#All],[Year]],$G380,All_India_Index_Upto_April23__134[[#All],[Month]],$H380,All_India_Index_Upto_April23__134[[#All],[Sector]],K$371) -> 175.175 | L380: =(K380-K379)/K379*100 -> -0.65689981 | N380: Sugar and Confectionery | O380: {=AVERAGEIFS(sugar_confections,months,"june",year,"2022",sector,"Rural+Urban")} -> 119.9 | P380: {=AVERAGEIFS(sugar_confections,months,"may",year,"2023",sector,"Rural+Urban")} -> 122.7 | Q380: =(P380-O380)/O380 -> 0.023352794
A381: Spices | B381: 221 | C381: 211.9 | D381: 218 | E381: Food and Beverages | G381: 2023 | H381: March | I381: =AVERAGEIFS(All_India_Index_Upto_April23__134[[#All],[Food buckts avg2]],All_India_Index_Upto_April23__134[[#All],[Year]],$G381,All_India_Index_Upto_April23__134[[#All],[Month]],$H381,All_India_Index_Upto_April23__134[[#All],[Sector]],I$371) -> 174.25 | J381: =AVERAGEIFS(All_India_Index_Upto_April23__134[[#All],[Food buckts avg2]],All_India_Index_Upto_April23__134[[#All],[Year]],$G381,All_India_Index_Upto_April23__134[[#All],[Month]],$H381,All_India_Index_Upto_April23__134[[#All],[Sector]],J$371) -> 176.88333 | K381: =AVERAGEIFS(All_India_Index_Upto_April23__134[[#All],[Food buckts avg2]],All_India_Index_Upto_April23__134[[#All],[Year]],$G381,All_India_Index_Upto_April23__134[[#All],[Month]],$H381,All_India_Index_Upto_April23__134[[#All],[Sector]],K$371) -> 175.18333 | L381: =(K381-K380)/K380*100 -> 0.0047571476 | N381: Spices | O381: {=AVERAGEIFS(spices,months,"june",year,"2022",sector,"Rural+Urban")} -> 187.1 | P381: {=AVERAGEIFS(spices,months,"May",year,"2023",sector,"Rural+Urban")} -> 218 | Q381: =(P381-O381)/O381 -> 0.16515232
A382: Non-alcoholic beverages | B382: 178.7 | C382: 165.9 | D382: 173.4 | E382: Food and Beverages | G382: 2023 | H382: April | I382: =AVERAGEIFS(All_India_Index_Upto_April23__134[[#All],[Food buckts avg2]],All_India_Index_Upto_April23__134[[#All],[Year]],$G382,All_India_Index_Upto_April23__134[[#All],[Month]],$H382,All_India_Index_Upto_April23__134[[#All],[Sector]],I$371) -> 174.89167 | J382: =AVERAGEIFS(All_India_Index_Upto_April23__134[[#All],[Food buckts avg2]],All_India_Index_Upto_April23__134[[#All],[Year]],$G382,All_India_Index_Upto_April23__134[[#All],[Month]],$H382,All_India_Index_Upto_April23__134[[#All],[Sector]],J$371) -> 177.96667 | K382: =AVERAGEIFS(All_India_Index_Upto_April23__134[[#All],[Food buckts avg2]],All_India_Index_Upto_April23__134[[#All],[Year]],$G382,All_India_Index_Upto_April23__134[[#All],[Month]],$H382,All_India_Index_Upto_April23__134[[#All],[Sector]],K$371) -> 175.975 | L382: =(K382-K381)/K381*100 -> 0.45190753 | N382: Non-alcoholic beverages | O382: {=AVERAGEIFS(non_alcoholic,months,"june",year,"2022",sector,"Rural+Urban")} -> 167.9 | P382: {=AVERAGEIFS(non_alcoholic,months,"May",year,"2023",sector,"Rural+Urban")} -> 173.4 | Q382: =(P382-O382)/O382 -> 0.032757594
A383: Prepared meals, snacks, sweets etc. | B383: 191.1 | C383: 197.7 | D383: 194.2 | E383: Food and Beverages | G383: 2023 | H383: May | I383: =AVERAGEIFS(All_India_Index_Upto_April23__134[[#All],[Food buckts avg2]],All_India_Index_Upto_April23__134[[#All],[Year]],$G383,All_India_Index_Upto_April23__134[[#All],[Month]],$H383,All_India_Index_Upto_April23__134[[#All],[Sector]],I$371) -> 176.15833 | J383: =AVERAGEIFS(All_India_Index_Upto_April23__134[[#All],[Food buckts avg2]],All_India_Index_Upto_April23__134[[#All],[Year]],$G383,All_India_Index_Upto_April23__134[[#All],[Month]],$H383,All_India_Index_Upto_April23__134[[#All],[Sector]],J$371) -> 179.33333 | K383: =AVERAGEIFS(All_India_Index_Upto_April23__134[[#All],[Food buckts avg2]],All_India_Index_Upto_April23__134[[#All],[Year]],$G383,All_India_Index_Upto_April23__134[[#All],[Month]],$H383,All_India_Index_Upto_April23__134[[#All],[Sector]],K$371) -> 177.31667 | L383: =(K383-K382)/K382*100 -> 0.7624189 | N383: Prepared meals, snacks, sweets etc. | O383: {=AVERAGEIFS(pre_meal,months,"june",year,"2022",sector,"Rural+Urban")} -> 183.9 | P383: {=AVERAGEIFS(pre_meal,months,"May",year,"2023",sector,"Rural+Urban")} -> 194.2 | Q383: =(P383-O383)/O383 -> 0.0560087
A384: Food and beverages | B384: 176.8 | C384: 183.1 | D384: 179.1 | E384: Food and Beverages

Sheet 4 .pandemic inflation
C8: Year | D8: Months | E8: Food and beverages | F8: Fuel and light | G8: Household goods and services | H8: Health | I8: Transport and communication
C9: 2019 | D9: february | E9: {=AVERAGEIFS(Food_beverages,year,$C9,months,$D9,sector,"rural+urban")} -> 137.5 | F9: {=AVERAGEIFS(Fuel_lights,year,$C9,months,$D9,sector,"rural+urban")} -> 138.4 | G9: {=AVERAGEIFS(house_goods_servies,year,$C9,months,$D9,sector,"rural+urban")} -> 143.7 | H9: {=AVERAGEIFS(health,year,$C9,months,$D9,sector,"rural+urban")} -> 145.6 | I9: {=AVERAGEIFS(trans_comu,year,$C9,months,$D9,sector,"rural+urban")} -> 123.9
C10: 2019 | D10: march | E10: {=AVERAGEIFS(Food_beverages,year,$C10,months,$D10,sector,"rural+urban")} -> 138.1 | F10: {=AVERAGEIFS(Fuel_lights,year,$C10,months,$D10,sector,"rural+urban")} -> 139.7 | G10: {=AVERAGEIFS(house_goods_servies,year,$C10,months,$D10,sector,"rural+urban")} -> 143.8 | H10: {=AVERAGEIFS(health,year,$C10,months,$D10,sector,"rural+urban")} -> 146.2 | I10: {=AVERAGEIFS(trans_comu,year,$C10,months,$D10,sector,"rural+urban")} -> 124.6
C11: 2019 | D11: may | E11: {=AVERAGEIFS(Food_beverages,year,$C11,months,$D11,sector,"rural+urban")} -> 140.9 | F11: {=AVERAGEIFS(Fuel_lights,year,$C11,months,$D11,sector,"rural+urban")} -> 140.3 | G11: {=AVERAGEIFS(house_goods_servies,year,$C11,months,$D11,sector,"rural+urban")} -> 143.7 | H11: {=AVERAGEIFS(health,year,$C11,months,$D11,sector,"rural+urban")} -> 146.9 | I11: {=AVERAGEIFS(trans_comu,year,$C11,months,$D11,sector,"rural+urban")} -> 124.9
C12: 2019 | D12: june | E12: {=AVERAGEIFS(Food_beverages,year,$C12,months,$D12,sector,"rural+urban")} -> 142.7 | F12: {=AVERAGEIFS(Fuel_lights,year,$C12,months,$D12,sector,"rural+urban")} -> 141.2 | G12: {=AVERAGEIFS(house_goods_servies,year,$C12,months,$D12,sector,"rural+urban")} -> 143.8 | H12: {=AVERAGEIFS(health,year,$C12,months,$D12,sector,"rural+urban")} -> 147.4 | I12: {=AVERAGEIFS(trans_comu,year,$C12,months,$D12,sector,"rural+urban")} -> 124.6
C13: 2019 | D13: july | E13: {=AVERAGEIFS(Food_beverages,year,$C13,months,$D13,sector,"rural+urban")} -> 144.7 | F13: {=AVERAGEIFS(Fuel_lights,year,$C13,months,$D13,sector,"rural+urban")} -> 139.3 | G13: {=AVERAGEIFS(house_goods_servies,year,$C13,months,$D13,sector,"rural+urban")} -> 144.2 | H13: {=AVERAGEIFS(health,year,$C13,months,$D13,sector,"rural+urban")} -> 147.9 | I13: {=AVERAGEIFS(trans_comu,year,$C13,months,$D13,sector,"rural+urban")} -> 125.6
C14: 2019 | D14: august | E14: {=AVERAGEIFS(Food_beverages,year,$C14,months,$D14,sector,"rural+urban")} -> 145.9 | F14: {=AVERAGEIFS(Fuel_lights,year,$C14,months,$D14,sector,"rural+urban")} -> 138.5 | G14: {=AVERAGEIFS(house_goods_servies,year,$C14,months,$D14,sector,"rural+urban")} -> 144.5 | H14: {=AVERAGEIFS(health,year,$C14,months,$D14,sector,"rural+urban")} -> 148.5 | I14: {=AVERAGEIFS(trans_comu,year,$C14,months,$D14,sector,"rural+urban")} -> 125.8
C15: 2019 | D15: september | E15: {=AVERAGEIFS(Food_beverages,year,$C15,months,$D15,sector,"rural+urban")} -> 147 | F15: {=AVERAGEIFS(Fuel_lights,year,$C15,months,$D15,sector,"rural+urban")} -> 139.2 | G15: {=AVERAGEIFS(house_goods_servies,year,$C15,months,$D15,sector,"rural+urban")} -> 144.6 | H15: {=AVERAGEIFS(health,year,$C15,months,$D15,sector,"rural+urban")} -> 149 | I15: {=AVERAGEIFS(trans_comu,year,$C15,months,$D15,sector,"rural+urban")} -> 126.1
